Workbook

Sheet README
A1: Northstar Consumer Brands Ltd — FP&A Operating Plan, Rolling Forecast & Scenario Modelling
A3: Portfolio case study | UK consumer/FMCG | Model date: 2 Oct 2026
A5: 1. Business case
A6: Northstar Consumer Brands Ltd is a fictional UK multi-division consumer business. Management needs a 2026 operating plan, rolling forecast and scenario model that explains revenue, gross margin and EBITDA performance by month and division. The model uses synthetic portfolio data so every assumption and calculation can be discussed transparently in interviews.
A12: 2. What this workbook demonstrates
A13: Driver-based revenue planning | B13: Units × ASP with division-level growth assumptions
A14: Budgeting | B14: 2026 monthly operating budget linked to 2025 actual run-rate
A15: Rolling forecast | B15: Jan–Sep actuals + Oct–Dec scenario-adjusted forecast
A16: Variance analysis | B16: Budget vs forecast revenue, gross profit and EBITDA
A17: Scenario planning | B17: Base / Upside / Downside operating assumptions
A18: Management reporting | B18: Executive KPI dashboard and decision-ready summaries
A19: Excel modelling | B19: Linked schedules, formula discipline and finance formatting conventions
A21: 3. Model navigation
A22: Assumptions | B22: Editable scenario and 2026 budget drivers
A23: Historical Actuals | B23: Synthetic monthly actuals from Jan-2024 to Sep-2026
A24: Budget 2026 | B24: Driver-based full-year 2026 budget
A25: Rolling Forecast | B25: Actuals through Sep-2026 plus Q4 forecast
A26: Variance Analysis | B26: Monthly and divisional budget-vs-forecast bridge
A27: Dashboard | B27: Executive KPI summary and charts
A28: Data Dictionary | B28: Definitions, units and modelling notes
A30: 4. Portfolio / interview note
A31: This is an independent portfolio project, not a live company engagement. Financial figures are synthetic. Use it to demonstrate modelling logic, FP&A judgement and management communication—not to claim realised business savings. A recruiter-safe phrasing is: 'Built a driver-based FP&A model covering revenue, COGS, payroll and operating expenses; produced a rolling forecast, scenario analysis and budget-versus-forecast variance reporting for a multi-division consumer business.'
A37: 5. Build 2 additions
A38: Build 2 adds detailed headcount/payroll planning, a capital expenditure and depreciation schedule, working-capital forecasting, a 13-week liquidity forecast, and an investment-appraisal business case. The payroll schedule now feeds the 2026 budget, while working capital and the cash forecast pull directly from the rolling forecast. This creates a more realistic FP&A model linking operating drivers to cash.
A46: 6. Build 3 additions
A47: Build 3 adds a full-year Price–Volume–Mix bridge, a gross-profit driver bridge, a probability-weighted Risks & Opportunities register, formula-driven management commentary and a CFO-style management pack. The project now moves beyond reporting into business partnering: explaining performance drivers, quantifying forecast uncertainty, prioritising actions and presenting an adjusted management outlook.
A56: 7. Final portfolio release
A57: Final release prepared for CV, LinkedIn and interview use. The workbook now includes a recruiter-facing Portfolio Summary sheet and is distributed with a README, project description, CV bullets, LinkedIn launch post, interview explanation and selected screenshots. All inputs are synthetic and should be described as an independent portfolio case study.

Sheet Assumptions
A1: Assumptions & Scenario Controls
A3: Blue font = hardcoded input | Black = formula | Green = cross-sheet link
A5: Active scenario
A6: Selected Scenario | B6: Base
A8: Scenario multipliers for Q4 rolling forecast
A9: Scenario | B9: Volume | C9: ASP / Price | D9: Unit Cost | E9: Marketing | F9: Other Opex
A10: Base | B10: 1 | C10: 1 | D10: 1 | E10: 1 | F10: 1
A11: Upside | B11: 1.05 | C11: 1.01 | D11: 0.99 | E11: 1 | F11: 0.99
A12: Downside | B12: 0.93 | C12: 0.99 | D12: 1.045 | E12: 1.06 | F12: 1.03
A14: Active scenario multipliers
A15: Metric | B15: Volume | C15: ASP / Price | D15: Unit Cost | E15: Marketing | F15: Other Opex
A16: Active | B16: =IF($B$6="Upside",B11,IF($B$6="Downside",B12,B10)) -> 1 | C16: =IF($B$6="Upside",C11,IF($B$6="Downside",C12,C10)) -> 1 | D16: =IF($B$6="Upside",D11,IF($B$6="Downside",D12,D10)) -> 1 | E16: =IF($B$6="Upside",E11,IF($B$6="Downside",E12,E10)) -> 1 | F16: =IF($B$6="Upside",F11,IF($B$6="Downside",F12,F10)) -> 1
A18: 2026 division budget assumptions
A19: Division | B19: Unit Growth | C19: ASP Growth | D19: Unit Cost Inflation | E19: Marketing % Revenue | F19: Payroll Growth | G19: Other Opex Growth
A20: Personal Care | B20: 0.055 | C20: 0.03 | D20: 0.035 | E20: 0.073 | F20: 0.04 | G20: 0.035
A21: Home Care | B21: 0.042 | C21: 0.028 | D21: 0.038 | E21: 0.061 | F21: 0.04 | G21: 0.035
A22: Nutrition & Wellness | B22: 0.08 | C22: 0.035 | D22: 0.042 | E22: 0.085 | F22: 0.045 | G22: 0.04
A23: Baby & Kids | B23: 0.068 | C23: 0.032 | D23: 0.04 | E23: 0.092 | F23: 0.045 | G23: 0.04
A24: Leisure & Lifestyle | B24: 0.035 | C24: 0.025 | D24: 0.045 | E24: 0.067 | F24: 0.04 | G24: 0.045
A26: Modelling notes
A27: Historical period | B27: Jan-2024 to Sep-2026 actuals
A28: Budget period | B28: Jan-2026 to Dec-2026
A29: Rolling forecast | B29: Jan-Sep actual; Oct-Dec forecast
A30: Units | B30: Physical units sold
A31: Financial units | B31: £000 unless otherwise stated
A32: Dataset source | B32: Synthetic portfolio dataset generated for this project

Sheet Historical Actuals
A1: Historical Actuals — Monthly Division Performance
A3: Period | B3: Division | C3: Units | D3: ASP (£/unit) | E3: Revenue (£000) | F3: Unit Cost (£/unit) | G3: COGS (£000) | H3: Gross Profit (£000) | I3: GP % | J3: Marketing (£000) | K3: Payroll (£000) | L3: Other Opex (£000) | M3: EBITDA (£000) | N3: EBITDA % | O3: Status
A4: 45292 | B4: Personal Care | C4: 110811 | D4: 8.34 | E4: =C4*D4/1000 -> 924.16374 | F4: 4.23 | G4: =C4*F4/1000 -> 468.73053 | H4: =E4-G4 -> 455.43321 | I4: =IFERROR(H4/E4,0) -> 0.49280576 | J4: 65.3 | K4: 119.4 | L4: 85 | M4: =H4-J4-K4-L4 -> 185.73321 | N4: =IFERROR(M4/E4,0) -> 0.20097435 | O4: Actual
A5: 45292 | B5: Home Care | C5: 88864 | D5: 10.13 | E5: =C5*D5/1000 -> 900.19232 | F5: 5.54 | G5: =C5*F5/1000 -> 492.30656 | H5: =E5-G5 -> 407.88576 | I5: =IFERROR(H5/E5,0) -> 0.45310958 | J5: 50.8 | K5: 100.6 | L5: 72 | M5: =H5-J5-K5-L5 -> 184.48576 | N5: =IFERROR(M5/E5,0) -> 0.20494038 | O5: Actual
A6: 45292 | B6: Nutrition & Wellness | C6: 64741 | D6: 14.73 | E6: =C6*D6/1000 -> 953.63493 | F6: 7.63 | G6: =C6*F6/1000 -> 493.97383 | H6: =E6-G6 -> 459.6611 | I6: =IFERROR(H6/E6,0) -> 0.4820095 | J6: 79.7 | K6: 90.7 | L6: 66.4 | M6: =H6-J6-K6-L6 -> 222.8611 | N6: =IFERROR(M6/E6,0) -> 0.23369645 | O6: Actual
A7: 45292 | B7: Baby & Kids | C7: 57959 | D7: 12.3 | E7: =C7*D7/1000 -> 712.8957 | F7: 6.4 | G7: =C7*F7/1000 -> 370.9376 | H7: =E7-G7 -> 341.9581 | I7: =IFERROR(H7/E7,0) -> 0.4796748 | J7: 66.9 | K7: 83.3 | L7: 59.5 | M7: =H7-J7-K7-L7 -> 132.2581 | N7: =IFERROR(M7/E7,0) -> 0.18552237 | O7: Actual
A8: 45292 | B8: Leisure & Lifestyle | C8: 46069 | D8: 19.45 | E8: =C8*D8/1000 -> 896.04205 | F8: 10.79 | G8: =C8*F8/1000 -> 497.08451 | H8: =E8-G8 -> 398.95754 | I8: =IFERROR(H8/E8,0) -> 0.44524422 | J8: 57 | K8: 77.3 | L8: 58.4 | M8: =H8-J8-K8-L8 -> 206.25754 | N8: =IFERROR(M8/E8,0) -> 0.23018734 | O8: Actual
A9: 45323 | B9: Personal Care | C9: 114510 | D9: 8.43 | E9: =C9*D9/1000 -> 965.3193 | F9: 4.25 | G9: =C9*F9/1000 -> 486.6675 | H9: =E9-G9 -> 478.6518 | I9: =IFERROR(H9/E9,0) -> 0.49584816 | J9: 76.8 | K9: 117.3 | L9: 84.3 | M9: =H9-J9-K9-L9 -> 200.2518 | N9: =IFERROR(M9/E9,0) -> 0.20744618 | O9: Actual
A10: 45323 | B10: Home Care | C10: 90387 | D10: 10.22 | E10: =C10*D10/1000 -> 923.75514 | F10: 5.6 | G10: =C10*F10/1000 -> 506.1672 | H10: =E10-G10 -> 417.58794 | I10: =IFERROR(H10/E10,0) -> 0.45205479 | J10: 57 | K10: 103 | L10: 69.7 | M10: =H10-J10-K10-L10 -> 187.88794 | N10: =IFERROR(M10/E10,0) -> 0.20339583 | O10: Actual
A11: 45323 | B11: Nutrition & Wellness | C11: 67097 | D11: 14.75 | E11: =C11*D11/1000 -> 989.68075 | F11: 7.52 | G11: =C11*F11/1000 -> 504.56944 | H11: =E11-G11 -> 485.11131 | I11: =IFERROR(H11/E11,0) -> 0.49016949 | J11: 78.6 | K11: 90.2 | L11: 65 | M11: =H11-J11-K11-L11 -> 251.31131 | N11: =IFERROR(M11/E11,0) -> 0.25393169 | O11: Actual
A12: 45323 | B12: Baby & Kids | C12: 58500 | D12: 12.37 | E12: =C12*D12/1000 -> 723.645 | F12: 6.33 | G12: =C12*F12/1000 -> 370.305 | H12: =E12-G12 -> 353.34 | I12: =IFERROR(H12/E12,0) -> 0.48827809 | J12: 62.8 | K12: 83 | L12: 62.9 | M12: =H12-J12-K12-L12 -> 144.64 | N12: =IFERROR(M12/E12,0) -> 0.19987701 | O12: Actual
A13: 45323 | B13: Leisure & Lifestyle | C13: 46073 | D13: 19.53 | E13: =C13*D13/1000 -> 899.80569 | F13: 10.81 | G13: =C13*F13/1000 -> 498.04913 | H13: =E13-G13 -> 401.75656 | I13: =IFERROR(H13/E13,0) -> 0.44649258 | J13: 63.4 | K13: 74.7 | L13: 57.5 | M13: =H13-J13-K13-L13 -> 206.15656 | N13: =IFERROR(M13/E13,0) -> 0.22911231 | O13: Actual
A14: 45352 | B14: Personal Care | C14: 120823 | D14: 8.42 | E14: =C14*D14/1000 -> 1017.3297 | F14: 4.26 | G14: =C14*F14/1000 -> 514.70598 | H14: =E14-G14 -> 502.62368 | I14: =IFERROR(H14/E14,0) -> 0.49406176 | J14: 77.5 | K14: 120 | L14: 85.6 | M14: =H14-J14-K14-L14 -> 219.52368 | N14: =IFERROR(M14/E14,0) -> 0.21578421 | O14: Actual
A15: 45352 | B15: Home Care | C15: 90324 | D15: 10.12 | E15: =C15*D15/1000 -> 914.07888 | F15: 5.53 | G15: =C15*F15/1000 -> 499.49172 | H15: =E15-G15 -> 414.58716 | I15: =IFERROR(H15/E15,0) -> 0.45355731 | J15: 53.7 | K15: 100.5 | L15: 74.2 | M15: =H15-J15-K15-L15 -> 186.18716 | N15: =IFERROR(M15/E15,0) -> 0.20368829 | O15: Actual
... A168: 46266 | B168: Leisure & Lifestyle | C168: 55276 | D168: 20.59 | E168: =C168*D168/1000 -> 1138.1328 | F168: 11.85 | G168: =C168*F168/1000 -> 655.0206 | H168: =E168-G168 -> 483.11224 | I168: =IFERROR(H168/E168,0) -> 0.4244779 | J168: 76.4 | K168: 83.1 | L168: 60.6 | M168: =H168-J168-K168-L168 -> 263.01224 | N168: =IFERROR(M168/E168,0) -> 0.23109099 | O168: Actual

Sheet Budget 2026
A1: 2026 Operating Budget — Driver-Based by Division
A3: Period | B3: Division | C3: PY Units | D3: Budget Units | E3: PY ASP | F3: Budget ASP | G3: PY Unit Cost | H3: Budget Unit Cost | I3: Revenue (£000) | J3: COGS (£000) | K3: Gross Profit (£000) | L3: GP % | M3: Marketing (£000) | N3: Payroll (£000) | O3: Other Opex (£000) | P3: EBITDA (£000)
A4: 46023 | B4: Personal Care | C4: ='Historical Actuals'!C64 -> 116513 | D4: =C4*(1+Assumptions!$B$20) -> 122921.21 | E4: ='Historical Actuals'!D64 -> 8.59 | F4: =E4*(1+Assumptions!$C$20) -> 8.8477 | G4: ='Historical Actuals'!F64 -> 4.42 | H4: =G4*(1+Assumptions!$D$20) -> 4.5747 | I4: =D4*F4/1000 -> 1087.57 | J4: =D4*H4/1000 -> 562.32768 | K4: =I4-J4 -> 525.24235 | L4: =IFERROR(K4/I4,0) -> 0.48295037 | M4: =I4*Assumptions!$E$20 -> 79.392612 | N4: ='Headcount & Payroll'!B37 -> 213.95031 | O4: ='Historical Actuals'!L64*(1+Assumptions!$G$20) -> 90.459 | P4: =K4-M4-N4-O4 -> 141.44043
A5: 46023 | B5: Home Care | C5: ='Historical Actuals'!C65 -> 89340 | D5: =C5*(1+Assumptions!$B$21) -> 93092.28 | E5: ='Historical Actuals'!D65 -> 10.5 | F5: =E5*(1+Assumptions!$C$21) -> 10.794 | G5: ='Historical Actuals'!F65 -> 5.69 | H5: =G5*(1+Assumptions!$D$21) -> 5.90622 | I5: =D5*F5/1000 -> 1004.8381 | J5: =D5*H5/1000 -> 549.82349 | K5: =I5-J5 -> 455.01458 | L5: =IFERROR(K5/I5,0) -> 0.45282379 | M5: =I5*Assumptions!$E$21 -> 61.295122 | N5: ='Headcount & Payroll'!B38 -> 178.82989 | O5: ='Historical Actuals'!L65*(1+Assumptions!$G$21) -> 78.3495 | P5: =K5-M5-N5-O5 -> 136.54007
A6: 46023 | B6: Nutrition & Wellness | C6: ='Historical Actuals'!C66 -> 71975 | D6: =C6*(1+Assumptions!$B$22) -> 77733 | E6: ='Historical Actuals'!D66 -> 15.23 | F6: =E6*(1+Assumptions!$C$22) -> 15.76305 | G6: ='Historical Actuals'!F66 -> 7.86 | H6: =G6*(1+Assumptions!$D$22) -> 8.19012 | I6: =D6*F6/1000 -> 1225.3092 | J6: =D6*H6/1000 -> 636.6426 | K6: =I6-J6 -> 588.66657 | L6: =IFERROR(K6/I6,0) -> 0.48042289 | M6: =I6*Assumptions!$E$22 -> 104.15128 | N6: ='Headcount & Payroll'!B39 -> 164.60602 | O6: ='Historical Actuals'!L66*(1+Assumptions!$G$22) -> 70.2 | P6: =K6-M6-N6-O6 -> 249.70927
A7: 46023 | B7: Baby & Kids | C7: ='Historical Actuals'!C67 -> 59518 | D7: =C7*(1+Assumptions!$B$23) -> 63565.224 | E7: ='Historical Actuals'!D67 -> 12.79 | F7: =E7*(1+Assumptions!$C$23) -> 13.19928 | G7: ='Historical Actuals'!F67 -> 6.63 | H7: =G7*(1+Assumptions!$D$23) -> 6.8952 | I7: =D7*F7/1000 -> 839.01519 | J7: =D7*H7/1000 -> 438.29493 | K7: =I7-J7 -> 400.72026 | L7: =IFERROR(K7/I7,0) -> 0.47760787 | M7: =I7*Assumptions!$E$23 -> 77.189397 | N7: ='Headcount & Payroll'!B40 -> 140.077 | O7: ='Historical Actuals'!L67*(1+Assumptions!$G$23) -> 65.208 | P7: =K7-M7-N7-O7 -> 118.24586
A8: 46023 | B8: Leisure & Lifestyle | C8: ='Historical Actuals'!C68 -> 47394 | D8: =C8*(1+Assumptions!$B$24) -> 49052.79 | E8: ='Historical Actuals'!D68 -> 19.94 | F8: =E8*(1+Assumptions!$C$24) -> 20.4385 | G8: ='Historical Actuals'!F68 -> 11.21 | H8: =G8*(1+Assumptions!$D$24) -> 11.71445 | I8: =D8*F8/1000 -> 1002.5654 | J8: =D8*H8/1000 -> 574.62646 | K8: =I8-J8 -> 427.93899 | L8: =IFERROR(K8/I8,0) -> 0.42684395 | M8: =I8*Assumptions!$E$24 -> 67.171885 | N8: ='Headcount & Payroll'!B41 -> 118.89419 | O8: ='Historical Actuals'!L68*(1+Assumptions!$G$24) -> 63.536 | P8: =K8-M8-N8-O8 -> 178.33692
A9: 46054 | B9: Personal Care | C9: ='Historical Actuals'!C69 -> 120448 | D9: =C9*(1+Assumptions!$B$20) -> 127072.64 | E9: ='Historical Actuals'!D69 -> 8.63 | F9: =E9*(1+Assumptions!$C$20) -> 8.8889 | G9: ='Historical Actuals'!F69 -> 4.39 | H9: =G9*(1+Assumptions!$D$20) -> 4.54365 | I9: =D9*F9/1000 -> 1129.536 | J9: =D9*H9/1000 -> 577.3736 | K9: =I9-J9 -> 552.16239 | L9: =IFERROR(K9/I9,0) -> 0.48884001 | M9: =I9*Assumptions!$E$20 -> 82.456127 | N9: ='Headcount & Payroll'!C37 -> 213.95031 | O9: ='Historical Actuals'!L69*(1+Assumptions!$G$20) -> 88.596 | P9: =K9-M9-N9-O9 -> 167.15995
A10: 46054 | B10: Home Care | C10: ='Historical Actuals'!C70 -> 92400 | D10: =C10*(1+Assumptions!$B$21) -> 96280.8 | E10: ='Historical Actuals'!D70 -> 10.48 | F10: =E10*(1+Assumptions!$C$21) -> 10.77344 | G10: ='Historical Actuals'!F70 -> 5.78 | H10: =G10*(1+Assumptions!$D$21) -> 5.99964 | I10: =D10*F10/1000 -> 1037.2754 | J10: =D10*H10/1000 -> 577.65014 | K10: =I10-J10 -> 459.62528 | L10: =IFERROR(K10/I10,0) -> 0.44310824 | M10: =I10*Assumptions!$E$21 -> 63.273801 | N10: ='Headcount & Payroll'!C38 -> 178.82989 | O10: ='Historical Actuals'!L70*(1+Assumptions!$G$21) -> 75.555 | P10: =K10-M10-N10-O10 -> 141.96659
A11: 46054 | B11: Nutrition & Wellness | C11: ='Historical Actuals'!C71 -> 72163 | D11: =C11*(1+Assumptions!$B$22) -> 77936.04 | E11: ='Historical Actuals'!D71 -> 15.28 | F11: =E11*(1+Assumptions!$C$22) -> 15.8148 | G11: ='Historical Actuals'!F71 -> 7.94 | H11: =G11*(1+Assumptions!$D$22) -> 8.27348 | I11: =D11*F11/1000 -> 1232.5429 | J11: =D11*H11/1000 -> 644.80227 | K11: =I11-J11 -> 587.74062 | L11: =IFERROR(K11/I11,0) -> 0.47685206 | M11: =I11*Assumptions!$E$22 -> 104.76615 | N11: ='Headcount & Payroll'!C39 -> 164.60602 | O11: ='Historical Actuals'!L71*(1+Assumptions!$G$22) -> 71.136 | P11: =K11-M11-N11-O11 -> 247.23246
A12: 46054 | B12: Baby & Kids | C12: ='Historical Actuals'!C72 -> 62174 | D12: =C12*(1+Assumptions!$B$23) -> 66401.832 | E12: ='Historical Actuals'!D72 -> 12.69 | F12: =E12*(1+Assumptions!$C$23) -> 13.09608 | G12: ='Historical Actuals'!F72 -> 6.64 | H12: =G12*(1+Assumptions!$D$23) -> 6.9056 | I12: =D12*F12/1000 -> 869.6037 | J12: =D12*H12/1000 -> 458.54449 | K12: =I12-J12 -> 411.05921 | L12: =IFERROR(K12/I12,0) -> 0.47269717 | M12: =I12*Assumptions!$E$23 -> 80.003541 | N12: ='Headcount & Payroll'!C40 -> 140.077 | O12: ='Historical Actuals'!L72*(1+Assumptions!$G$23) -> 64.376 | P12: =K12-M12-N12-O12 -> 126.60268
A13: 46054 | B13: Leisure & Lifestyle | C13: ='Historical Actuals'!C73 -> 47720 | D13: =C13*(1+Assumptions!$B$24) -> 49390.2 | E13: ='Historical Actuals'!D73 -> 19.85 | F13: =E13*(1+Assumptions!$C$24) -> 20.34625 | G13: ='Historical Actuals'!F73 -> 11.24 | H13: =G13*(1+Assumptions!$D$24) -> 11.7458 | I13: =D13*F13/1000 -> 1004.9054 | J13: =D13*H13/1000 -> 580.12741 | K13: =I13-J13 -> 424.77795 | L13: =IFERROR(K13/I13,0) -> 0.42270443 | M13: =I13*Assumptions!$E$24 -> 67.328659 | N13: ='Headcount & Payroll'!C41 -> 118.89419 | O13: ='Historical Actuals'!L73*(1+Assumptions!$G$24) -> 60.819 | P13: =K13-M13-N13-O13 -> 177.7361
A14: 46082 | B14: Personal Care | C14: ='Historical Actuals'!C74 -> 121346 | D14: =C14*(1+Assumptions!$B$20) -> 128020.03 | E14: ='Historical Actuals'!D74 -> 8.64 | F14: =E14*(1+Assumptions!$C$20) -> 8.8992 | G14: ='Historical Actuals'!F74 -> 4.38 | H14: =G14*(1+Assumptions!$D$20) -> 4.5333 | I14: =D14*F14/1000 -> 1139.2759 | J14: =D14*H14/1000 -> 580.3532 | K14: =I14-J14 -> 558.92265 | L14: =IFERROR(K14/I14,0) -> 0.49059466 | M14: =I14*Assumptions!$E$20 -> 83.167137 | N14: ='Headcount & Payroll'!D37 -> 223.26838 | O14: ='Historical Actuals'!L74*(1+Assumptions!$G$20) -> 88.389 | P14: =K14-M14-N14-O14 -> 164.09813
A15: 46082 | B15: Home Care | C15: ='Historical Actuals'!C75 -> 97823 | D15: =C15*(1+Assumptions!$B$21) -> 101931.57 | E15: ='Historical Actuals'!D75 -> 10.38 | F15: =E15*(1+Assumptions!$C$21) -> 10.67064 | G15: ='Historical Actuals'!F75 -> 5.8 | H15: =G15*(1+Assumptions!$D$21) -> 6.0204 | I15: =D15*F15/1000 -> 1087.675 | J15: =D15*H15/1000 -> 613.6688 | K15: =I15-J15 -> 474.00625 | L15: =IFERROR(K15/I15,0) -> 0.43579767 | M15: =I15*Assumptions!$E$21 -> 66.348178 | N15: ='Headcount & Payroll'!D38 -> 187.6939 | O15: ='Historical Actuals'!L75*(1+Assumptions!$G$21) -> 76.6935 | P15: =K15-M15-N15-O15 -> 143.27067
A16: 46082 | B16: Nutrition & Wellness | C16: ='Historical Actuals'!C76 -> 73634 | D16: =C16*(1+Assumptions!$B$22) -> 79524.72 | E16: ='Historical Actuals'!D76 -> 15.3 | F16: =E16*(1+Assumptions!$C$22) -> 15.8355 | G16: ='Historical Actuals'!F76 -> 7.89 | H16: =G16*(1+Assumptions!$D$22) -> 8.22138 | I16: =D16*F16/1000 -> 1259.3137 | J16: =D16*H16/1000 -> 653.80294 | K16: =I16-J16 -> 605.51076 | L16: =IFERROR(K16/I16,0) -> 0.48082599 | M16: =I16*Assumptions!$E$22 -> 107.04166 | N16: ='Headcount & Payroll'!D39 -> 177.23081 | O16: ='Historical Actuals'!L76*(1+Assumptions!$G$22) -> 72.8 | P16: =K16-M16-N16-O16 -> 248.43828
A17: 46082 | B17: Baby & Kids | C17: ='Historical Actuals'!C77 -> 63999 | D17: =C17*(1+Assumptions!$B$23) -> 68350.932 | E17: ='Historical Actuals'!D77 -> 12.78 | F17: =E17*(1+Assumptions!$C$23) -> 13.18896 | G17: ='Historical Actuals'!F77 -> 6.62 | H17: =G17*(1+Assumptions!$D$23) -> 6.8848 | I17: =D17*F17/1000 -> 901.47771 | J17: =D17*H17/1000 -> 470.5825 | K17: =I17-J17 -> 430.89521 | L17: =IFERROR(K17/I17,0) -> 0.47798765 | M17: =I17*Assumptions!$E$23 -> 82.935949 | N17: ='Headcount & Payroll'!D40 -> 152.75115 | O17: ='Historical Actuals'!L77*(1+Assumptions!$G$23) -> 67.704 | P17: =K17-M17-N17-O17 -> 127.50412
A18: 46082 | B18: Leisure & Lifestyle | C18: ='Historical Actuals'!C78 -> 52191 | D18: =C18*(1+Assumptions!$B$24) -> 54017.685 | E18: ='Historical Actuals'!D78 -> 20.04 | F18: =E18*(1+Assumptions!$C$24) -> 20.541 | G18: ='Historical Actuals'!F78 -> 11.37 | H18: =G18*(1+Assumptions!$D$24) -> 11.88165 | I18: =D18*F18/1000 -> 1109.5773 | J18: =D18*H18/1000 -> 641.81923 | K18: =I18-J18 -> 467.75804 | L18: =IFERROR(K18/I18,0) -> 0.42156419 | M18: =I18*Assumptions!$E$24 -> 74.341677 | N18: ='Headcount & Payroll'!D41 -> 127.77794 | O18: ='Historical Actuals'!L78*(1+Assumptions!$G$24) -> 62.909 | P18: =K18-M18-N18-O18 -> 202.72943
A19: 46113 | B19: Personal Care | C19: ='Historical Actuals'!C79 -> 126739 | D19: =C19*(1+Assumptions!$B$20) -> 133709.64 | E19: ='Historical Actuals'!D79 -> 8.65 | F19: =E19*(1+Assumptions!$C$20) -> 8.9095 | G19: ='Historical Actuals'!F79 -> 4.41 | H19: =G19*(1+Assumptions!$D$20) -> 4.56435 | I19: =D19*F19/1000 -> 1191.2861 | J19: =D19*H19/1000 -> 610.29762 | K19: =I19-J19 -> 580.98846 | L19: =IFERROR(K19/I19,0) -> 0.48769852 | M19: =I19*Assumptions!$E$20 -> 86.963884 | N19: ='Headcount & Payroll'!E37 -> 223.26838 | O19: ='Historical Actuals'!L79*(1+Assumptions!$G$20) -> 90.873 | P19: =K19-M19-N19-O19 -> 179.8832
A20: 46113 | B20: Home Care | C20: ='Historical Actuals'!C80 -> 99562 | D20: =C20*(1+Assumptions!$B$21) -> 103743.6 | E20: ='Historical Actuals'!D80 -> 10.47 | F20: =E20*(1+Assumptions!$C$21) -> 10.76316 | G20: ='Historical Actuals'!F80 -> 5.78 | H20: =G20*(1+Assumptions!$D$21) -> 5.99964 | I20: =D20*F20/1000 -> 1116.609 | J20: =D20*H20/1000 -> 622.42428 | K20: =I20-J20 -> 494.18473 | L20: =IFERROR(K20/I20,0) -> 0.44257634 | M20: =I20*Assumptions!$E$21 -> 68.11315 | N20: ='Headcount & Payroll'!E38 -> 187.6939 | O20: ='Historical Actuals'!L80*(1+Assumptions!$G$21) -> 75.969 | P20: =K20-M20-N20-O20 -> 162.40869
A21: 46113 | B21: Nutrition & Wellness | C21: ='Historical Actuals'!C81 -> 74888 | D21: =C21*(1+Assumptions!$B$22) -> 80879.04 | E21: ='Historical Actuals'!D81 -> 15.14 | F21: =E21*(1+Assumptions!$C$22) -> 15.6699 | G21: ='Historical Actuals'!F81 -> 7.9 | H21: =G21*(1+Assumptions!$D$22) -> 8.2318 | I21: =D21*F21/1000 -> 1267.3665 | J21: =D21*H21/1000 -> 665.78008 | K21: =I21-J21 -> 601.58639 | L21: =IFERROR(K21/I21,0) -> 0.47467438 | M21: =I21*Assumptions!$E$22 -> 107.72615 | N21: ='Headcount & Payroll'!E39 -> 177.23081 | O21: ='Historical Actuals'!L81*(1+Assumptions!$G$22) -> 71.968 | P21: =K21-M21-N21-O21 -> 244.66143
A22: 46113 | B22: Baby & Kids | C22: ='Historical Actuals'!C82 -> 65780 | D22: =C22*(1+Assumptions!$B$23) -> 70253.04 | E22: ='Historical Actuals'!D82 -> 12.63 | F22: =E22*(1+Assumptions!$C$23) -> 13.03416 | G22: ='Historical Actuals'!F82 -> 6.58 | H22: =G22*(1+Assumptions!$D$23) -> 6.8432 | I22: =D22*F22/1000 -> 915.68936 | J22: =D22*H22/1000 -> 480.7556 | K22: =I22-J22 -> 434.93376 | L22: =IFERROR(K22/I22,0) -> 0.47497959 | M22: =I22*Assumptions!$E$23 -> 84.243421 | N22: ='Headcount & Payroll'!E40 -> 152.75115 | O22: ='Historical Actuals'!L82*(1+Assumptions!$G$23) -> 64.272 | P22: =K22-M22-N22-O22 -> 133.66719
A23: 46113 | B23: Leisure & Lifestyle | C23: ='Historical Actuals'!C83 -> 51025 | D23: =C23*(1+Assumptions!$B$24) -> 52810.875 | E23: ='Historical Actuals'!D83 -> 20.14 | F23: =E23*(1+Assumptions!$C$24) -> 20.6435 | G23: ='Historical Actuals'!F83 -> 11.34 | H23: =G23*(1+Assumptions!$D$24) -> 11.8503 | I23: =D23*F23/1000 -> 1090.2013 | J23: =D23*H23/1000 -> 625.82471 | K23: =I23-J23 -> 464.37659 | L23: =IFERROR(K23/I23,0) -> 0.4259549 | M23: =I23*Assumptions!$E$24 -> 73.043487 | N23: ='Headcount & Payroll'!E41 -> 127.77794 | O23: ='Historical Actuals'!L83*(1+Assumptions!$G$24) -> 63.8495 | P23: =K23-M23-N23-O23 -> 199.70566
A24: 46143 | B24: Personal Care | C24: ='Historical Actuals'!C84 -> 125946 | D24: =C24*(1+Assumptions!$B$20) -> 132873.03 | E24: ='Historical Actuals'!D84 -> 8.55 | F24: =E24*(1+Assumptions!$C$20) -> 8.8065 | G24: ='Historical Actuals'!F84 -> 4.4 | H24: =G24*(1+Assumptions!$D$20) -> 4.554 | I24: =D24*F24/1000 -> 1170.1463 | J24: =D24*H24/1000 -> 605.10378 | K24: =I24-J24 -> 565.04256 | L24: =IFERROR(K24/I24,0) -> 0.48288196 | M24: =I24*Assumptions!$E$20 -> 85.420683 | N24: ='Headcount & Payroll'!F37 -> 223.26838 | O24: ='Historical Actuals'!L84*(1+Assumptions!$G$20) -> 92.8395 | P24: =K24-M24-N24-O24 -> 163.514
A25: 46143 | B25: Home Care | C25: ='Historical Actuals'!C85 -> 100105 | D25: =C25*(1+Assumptions!$B$21) -> 104309.41 | E25: ='Historical Actuals'!D85 -> 10.51 | F25: =E25*(1+Assumptions!$C$21) -> 10.80428 | G25: ='Historical Actuals'!F85 -> 5.77 | H25: =G25*(1+Assumptions!$D$21) -> 5.98926 | I25: =D25*F25/1000 -> 1126.9881 | J25: =D25*H25/1000 -> 624.73618 | K25: =I25-J25 -> 502.2519 | L25: =IFERROR(K25/I25,0) -> 0.44565857 | M25: =I25*Assumptions!$E$21 -> 68.746272 | N25: ='Headcount & Payroll'!F38 -> 187.6939 | O25: ='Historical Actuals'!L85*(1+Assumptions!$G$21) -> 75.6585 | P25: =K25-M25-N25-O25 -> 170.15323
A26: 46143 | B26: Nutrition & Wellness | C26: ='Historical Actuals'!C86 -> 78035 | D26: =C26*(1+Assumptions!$B$22) -> 84277.8 | E26: ='Historical Actuals'!D86 -> 15.07 | F26: =E26*(1+Assumptions!$C$22) -> 15.59745 | G26: ='Historical Actuals'!F86 -> 7.86 | H26: =G26*(1+Assumptions!$D$22) -> 8.19012 | I26: =D26*F26/1000 -> 1314.5188 | J26: =D26*H26/1000 -> 690.2453 | K26: =I26-J26 -> 624.27348 | L26: =IFERROR(K26/I26,0) -> 0.47490648 | M26: =I26*Assumptions!$E$22 -> 111.7341 | N26: ='Headcount & Payroll'!F39 -> 177.23081 | O26: ='Historical Actuals'!L86*(1+Assumptions!$G$22) -> 69.368 | P26: =K26-M26-N26-O26 -> 265.94057
A27: 46143 | B27: Baby & Kids | C27: ='Historical Actuals'!C87 -> 66636 | D27: =C27*(1+Assumptions!$B$23) -> 71167.248 | E27: ='Historical Actuals'!D87 -> 12.65 | F27: =E27*(1+Assumptions!$C$23) -> 13.0548 | G27: ='Historical Actuals'!F87 -> 6.61 | H27: =G27*(1+Assumptions!$D$23) -> 6.8744 | I27: =D27*F27/1000 -> 929.07419 | J27: =D27*H27/1000 -> 489.23213 | K27: =I27-J27 -> 439.84206 | L27: =IFERROR(K27/I27,0) -> 0.47341974 | M27: =I27*Assumptions!$E$23 -> 85.474825 | N27: ='Headcount & Payroll'!F40 -> 152.75115 | O27: ='Historical Actuals'!L87*(1+Assumptions!$G$23) -> 65.936 | P27: =K27-M27-N27-O27 -> 135.68009
A28: 46143 | B28: Leisure & Lifestyle | C28: ='Historical Actuals'!C88 -> 51102 | D28: =C28*(1+Assumptions!$B$24) -> 52890.57 | E28: ='Historical Actuals'!D88 -> 20.05 | F28: =E28*(1+Assumptions!$C$24) -> 20.55125 | G28: ='Historical Actuals'!F88 -> 11.22 | H28: =G28*(1+Assumptions!$D$24) -> 11.7249 | I28: =D28*F28/1000 -> 1086.9673 | J28: =D28*H28/1000 -> 620.13664 | K28: =I28-J28 -> 466.83068 | L28: =IFERROR(K28/I28,0) -> 0.42947996 | M28: =I28*Assumptions!$E$24 -> 72.826811 | N28: ='Headcount & Payroll'!F41 -> 127.77794 | O28: ='Historical Actuals'!L88*(1+Assumptions!$G$24) -> 62.1775 | P28: =K28-M28-N28-O28 -> 204.04843
A29: 46174 | B29: Personal Care | C29: ='Historical Actuals'!C89 -> 126862 | D29: =C29*(1+Assumptions!$B$20) -> 133839.41 | E29: ='Historical Actuals'!D89 -> 8.59 | F29: =E29*(1+Assumptions!$C$20) -> 8.8477 | G29: ='Historical Actuals'!F89 -> 4.44 | H29: =G29*(1+Assumptions!$D$20) -> 4.5954 | I29: =D29*F29/1000 -> 1184.1709 | J29: =D29*H29/1000 -> 615.04562 | K29: =I29-J29 -> 569.12532 | L29: =IFERROR(K29/I29,0) -> 0.48061078 | M29: =I29*Assumptions!$E$20 -> 86.444479 | N29: ='Headcount & Payroll'!G37 -> 215.50003 | O29: ='Historical Actuals'!L89*(1+Assumptions!$G$20) -> 92.115 | P29: =K29-M29-N29-O29 -> 175.06581
A30: 46174 | B30: Home Care | C30: ='Historical Actuals'!C90 -> 100850 | D30: =C30*(1+Assumptions!$B$21) -> 105085.7 | E30: ='Historical Actuals'!D90 -> 10.4 | F30: =E30*(1+Assumptions!$C$21) -> 10.6912 | G30: ='Historical Actuals'!F90 -> 5.69 | H30: =G30*(1+Assumptions!$D$21) -> 5.90622 | I30: =D30*F30/1000 -> 1123.4922 | J30: =D30*H30/1000 -> 620.65926 | K30: =I30-J30 -> 502.83297 | L30: =IFERROR(K30/I30,0) -> 0.44756248 | M30: =I30*Assumptions!$E$21 -> 68.533026 | N30: ='Headcount & Payroll'!G38 -> 180.19206 | O30: ='Historical Actuals'!L90*(1+Assumptions!$G$21) -> 76.2795 | P30: =K30-M30-N30-O30 -> 177.82838
A31: 46174 | B31: Nutrition & Wellness | C31: ='Historical Actuals'!C91 -> 80749 | D31: =C31*(1+Assumptions!$B$22) -> 87208.92 | E31: ='Historical Actuals'!D91 -> 15.25 | F31: =E31*(1+Assumptions!$C$22) -> 15.78375 | G31: ='Historical Actuals'!F91 -> 7.92 | H31: =G31*(1+Assumptions!$D$22) -> 8.25264 | I31: =D31*F31/1000 -> 1376.4838 | J31: =D31*H31/1000 -> 719.70382 | K31: =I31-J31 -> 656.77997 | L31: =IFERROR(K31/I31,0) -> 0.47714326 | M31: =I31*Assumptions!$E$22 -> 117.00112 | N31: ='Headcount & Payroll'!G39 -> 169.65001 | O31: ='Historical Actuals'!L91*(1+Assumptions!$G$22) -> 69.576 | P31: =K31-M31-N31-O31 -> 300.55283
A32: 46174 | B32: Baby & Kids | C32: ='Historical Actuals'!C92 -> 65799 | D32: =C32*(1+Assumptions!$B$23) -> 70273.332 | E32: ='Historical Actuals'!D92 -> 12.65 | F32: =E32*(1+Assumptions!$C$23) -> 13.0548 | G32: ='Historical Actuals'!F92 -> 6.53 | H32: =G32*(1+Assumptions!$D$23) -> 6.7912 | I32: =D32*F32/1000 -> 917.40429 | J32: =D32*H32/1000 -> 477.24025 | K32: =I32-J32 -> 440.16404 | L32: =IFERROR(K32/I32,0) -> 0.47979287 | M32: =I32*Assumptions!$E$23 -> 84.401195 | N32: ='Headcount & Payroll'!G40 -> 149.00023 | O32: ='Historical Actuals'!L92*(1+Assumptions!$G$23) -> 64.376 | P32: =K32-M32-N32-O32 -> 142.38662
A33: 46174 | B33: Leisure & Lifestyle | C33: ='Historical Actuals'!C93 -> 54630 | D33: =C33*(1+Assumptions!$B$24) -> 56542.05 | E33: ='Historical Actuals'!D93 -> 20.09 | F33: =E33*(1+Assumptions!$C$24) -> 20.59225 | G33: ='Historical Actuals'!F93 -> 11.22 | H33: =G33*(1+Assumptions!$D$24) -> 11.7249 | I33: =D33*F33/1000 -> 1164.328 | J33: =D33*H33/1000 -> 662.94988 | K33: =I33-J33 -> 501.37815 | L33: =IFERROR(K33/I33,0) -> 0.43061589 | M33: =I33*Assumptions!$E$24 -> 78.009978 | N33: ='Headcount & Payroll'!G41 -> 127.77794 | O33: ='Historical Actuals'!L93*(1+Assumptions!$G$24) -> 61.028 | P33: =K33-M33-N33-O33 -> 234.56223
A34: 46204 | B34: Personal Care | C34: ='Historical Actuals'!C94 -> 133630 | D34: =C34*(1+Assumptions!$B$20) -> 140979.65 | E34: ='Historical Actuals'!D94 -> 8.68 | F34: =E34*(1+Assumptions!$C$20) -> 8.9404 | G34: ='Historical Actuals'!F94 -> 4.37 | H34: =G34*(1+Assumptions!$D$20) -> 4.52295 | I34: =D34*F34/1000 -> 1260.4145 | J34: =D34*H34/1000 -> 637.64391 | K34: =I34-J34 -> 622.77055 | L34: =IFERROR(K34/I34,0) -> 0.49409982 | M34: =I34*Assumptions!$E$20 -> 92.010256 | N34: ='Headcount & Payroll'!H37 -> 215.50003 | O34: ='Historical Actuals'!L94*(1+Assumptions!$G$20) -> 91.08 | P34: =K34-M34-N34-O34 -> 224.18027
A35: 46204 | B35: Home Care | C35: ='Historical Actuals'!C95 -> 106930 | D35: =C35*(1+Assumptions!$B$21) -> 111421.06 | E35: ='Historical Actuals'!D95 -> 10.45 | F35: =E35*(1+Assumptions!$C$21) -> 10.7426 | G35: ='Historical Actuals'!F95 -> 5.79 | H35: =G35*(1+Assumptions!$D$21) -> 6.01002 | I35: =D35*F35/1000 -> 1196.9519 | J35: =D35*H35/1000 -> 669.6428 | K35: =I35-J35 -> 527.30908 | L35: =IFERROR(K35/I35,0) -> 0.44054326 | M35: =I35*Assumptions!$E$21 -> 73.014065 | N35: ='Headcount & Payroll'!H38 -> 180.19206 | O35: ='Historical Actuals'!L95*(1+Assumptions!$G$21) -> 77.832 | P35: =K35-M35-N35-O35 -> 196.27095
A36: 46204 | B36: Nutrition & Wellness | C36: ='Historical Actuals'!C96 -> 78422 | D36: =C36*(1+Assumptions!$B$22) -> 84695.76 | E36: ='Historical Actuals'!D96 -> 15.25 | F36: =E36*(1+Assumptions!$C$22) -> 15.78375 | G36: ='Historical Actuals'!F96 -> 7.96 | H36: =G36*(1+Assumptions!$D$22) -> 8.29432 | I36: =D36*F36/1000 -> 1336.8167 | J36: =D36*H36/1000 -> 702.49374 | K36: =I36-J36 -> 634.32297 | L36: =IFERROR(K36/I36,0) -> 0.47450257 | M36: =I36*Assumptions!$E$22 -> 113.62942 | N36: ='Headcount & Payroll'!H39 -> 169.65001 | O36: ='Historical Actuals'!L96*(1+Assumptions!$G$22) -> 73.424 | P36: =K36-M36-N36-O36 -> 277.61953
A37: 46204 | B37: Baby & Kids | C37: ='Historical Actuals'!C97 -> 70093 | D37: =C37*(1+Assumptions!$B$23) -> 74859.324 | E37: ='Historical Actuals'!D97 -> 12.69 | F37: =E37*(1+Assumptions!$C$23) -> 13.09608 | G37: ='Historical Actuals'!F97 -> 6.58 | H37: =G37*(1+Assumptions!$D$23) -> 6.8432 | I37: =D37*F37/1000 -> 980.3637 | J37: =D37*H37/1000 -> 512.27733 | K37: =I37-J37 -> 468.08637 | L37: =IFERROR(K37/I37,0) -> 0.47746196 | M37: =I37*Assumptions!$E$23 -> 90.19346 | N37: ='Headcount & Payroll'!H40 -> 149.00023 | O37: ='Historical Actuals'!L97*(1+Assumptions!$G$23) -> 64.896 | P37: =K37-M37-N37-O37 -> 163.99668
A38: 46204 | B38: Leisure & Lifestyle | C38: ='Historical Actuals'!C98 -> 55722 | D38: =C38*(1+Assumptions!$B$24) -> 57672.27 | E38: ='Historical Actuals'!D98 -> 20.11 | F38: =E38*(1+Assumptions!$C$24) -> 20.61275 | G38: ='Historical Actuals'!F98 -> 11.21 | H38: =G38*(1+Assumptions!$D$24) -> 11.71445 | I38: =D38*F38/1000 -> 1188.7841 | J38: =D38*H38/1000 -> 675.59892 | K38: =I38-J38 -> 513.18516 | L38: =IFERROR(K38/I38,0) -> 0.43168912 | M38: =I38*Assumptions!$E$24 -> 79.648534 | N38: ='Headcount & Payroll'!H41 -> 127.77794 | O38: ='Historical Actuals'!L98*(1+Assumptions!$G$24) -> 64.163 | P38: =K38-M38-N38-O38 -> 241.59569
A39: 46235 | B39: Personal Care | C39: ='Historical Actuals'!C99 -> 127601 | D39: =C39*(1+Assumptions!$B$20) -> 134619.05 | E39: ='Historical Actuals'!D99 -> 8.61 | F39: =E39*(1+Assumptions!$C$20) -> 8.8683 | G39: ='Historical Actuals'!F99 -> 4.44 | H39: =G39*(1+Assumptions!$D$20) -> 4.5954 | I39: =D39*F39/1000 -> 1193.8422 | J39: =D39*H39/1000 -> 618.62841 | K39: =I39-J39 -> 575.21376 | L39: =IFERROR(K39/I39,0) -> 0.48181726 | M39: =I39*Assumptions!$E$20 -> 87.150478 | N39: ='Headcount & Payroll'!I37 -> 215.50003 | O39: ='Historical Actuals'!L99*(1+Assumptions!$G$20) -> 91.908 | P39: =K39-M39-N39-O39 -> 180.65525
A40: 46235 | B40: Home Care | C40: ='Historical Actuals'!C100 -> 99964 | D40: =C40*(1+Assumptions!$B$21) -> 104162.49 | E40: ='Historical Actuals'!D100 -> 10.46 | F40: =E40*(1+Assumptions!$C$21) -> 10.75288 | G40: ='Historical Actuals'!F100 -> 5.75 | H40: =G40*(1+Assumptions!$D$21) -> 5.9685 | I40: =D40*F40/1000 -> 1120.0467 | J40: =D40*H40/1000 -> 621.69381 | K40: =I40-J40 -> 498.35292 | L40: =IFERROR(K40/I40,0) -> 0.4449394 | M40: =I40*Assumptions!$E$21 -> 68.322851 | N40: ='Headcount & Payroll'!I38 -> 180.19206 | O40: ='Historical Actuals'!L100*(1+Assumptions!$G$21) -> 79.074 | P40: =K40-M40-N40-O40 -> 170.76401
A41: 46235 | B41: Nutrition & Wellness | C41: ='Historical Actuals'!C101 -> 79423 | D41: =C41*(1+Assumptions!$B$22) -> 85776.84 | E41: ='Historical Actuals'!D101 -> 15.08 | F41: =E41*(1+Assumptions!$C$22) -> 15.6078 | G41: ='Historical Actuals'!F101 -> 7.96 | H41: =G41*(1+Assumptions!$D$22) -> 8.29432 | I41: =D41*F41/1000 -> 1338.7878 | J41: =D41*H41/1000 -> 711.46056 | K41: =I41-J41 -> 627.3272 | L41: =IFERROR(K41/I41,0) -> 0.46857853 | M41: =I41*Assumptions!$E$22 -> 113.79696 | N41: ='Headcount & Payroll'!I39 -> 169.65001 | O41: ='Historical Actuals'!L101*(1+Assumptions!$G$22) -> 71.552 | P41: =K41-M41-N41-O41 -> 272.32823
...

Sheet Rolling Forecast
A1: 2026 Rolling Forecast — Jan–Sep Actual + Oct–Dec Scenario Forecast
A3: Period | B3: Division | C3: Source | D3: Units | E3: ASP (£/unit) | F3: Revenue (£000) | G3: Unit Cost (£/unit) | H3: COGS (£000) | I3: Gross Profit (£000) | J3: GP % | K3: Marketing (£000) | L3: Payroll (£000) | M3: Other Opex (£000) | N3: EBITDA (£000) | O3: EBITDA % | P3: Scenario
A4: 46023 | B4: Personal Care | C4: Actual | D4: ='Historical Actuals'!C124 -> 116195 | E4: ='Historical Actuals'!D124 -> 8.9 | F4: ='Historical Actuals'!E124 -> 1034.1355 | G4: ='Historical Actuals'!F124 -> 4.61 | H4: ='Historical Actuals'!G124 -> 535.65895 | I4: ='Historical Actuals'!H124 -> 498.47655 | J4: ='Historical Actuals'!I124 -> 0.48202247 | K4: ='Historical Actuals'!J124 -> 77.5 | ... O4: ='Historical Actuals'!N124 -> 0.1911515 | P4: Actual
A5: 46023 | B5: Home Care | C5: Actual | D5: ='Historical Actuals'!C125 -> 96461 | E5: ='Historical Actuals'!D125 -> 10.69 | F5: ='Historical Actuals'!E125 -> 1031.1681 | G5: ='Historical Actuals'!F125 -> 5.91 | H5: ='Historical Actuals'!G125 -> 570.08451 | I5: ='Historical Actuals'!H125 -> 461.08358 | J5: ='Historical Actuals'!I125 -> 0.44714687 | K5: ='Historical Actuals'!J125 -> 65.5 | ... O5: ='Historical Actuals'!N125 -> 0.20140614 | P5: Actual
A6: 46023 | B6: Nutrition & Wellness | C6: Actual | D6: ='Historical Actuals'!C126 -> 76766 | E6: ='Historical Actuals'!D126 -> 15.49 | F6: ='Historical Actuals'!E126 -> 1189.1053 | G6: ='Historical Actuals'!F126 -> 8.19 | H6: ='Historical Actuals'!G126 -> 628.71354 | I6: ='Historical Actuals'!H126 -> 560.3918 | J6: ='Historical Actuals'!I126 -> 0.47127179 | K6: ='Historical Actuals'!J126 -> 100.8 | ... O6: ='Historical Actuals'!N126 -> 0.24530358 | P6: Actual
A7: 46023 | B7: Baby & Kids | C7: Actual | D7: ='Historical Actuals'!C127 -> 63198 | E7: ='Historical Actuals'!D127 -> 13.01 | F7: ='Historical Actuals'!E127 -> 822.20598 | G7: ='Historical Actuals'!F127 -> 6.86 | H7: ='Historical Actuals'!G127 -> 433.53828 | I7: ='Historical Actuals'!H127 -> 388.6677 | J7: ='Historical Actuals'!I127 -> 0.4727133 | K7: ='Historical Actuals'!J127 -> 79.1 | ... O7: ='Historical Actuals'!N127 -> 0.18665359 | P7: Actual
A8: 46023 | B8: Leisure & Lifestyle | C8: Actual | D8: ='Historical Actuals'!C128 -> 50047 | E8: ='Historical Actuals'!D128 -> 20.66 | F8: ='Historical Actuals'!E128 -> 1033.971 | G8: ='Historical Actuals'!F128 -> 11.82 | H8: ='Historical Actuals'!G128 -> 591.55554 | I8: ='Historical Actuals'!H128 -> 442.41548 | J8: ='Historical Actuals'!I128 -> 0.42787996 | K8: ='Historical Actuals'!J128 -> 70.9 | ... O8: ='Historical Actuals'!N128 -> 0.2208142 | P8: Actual
A9: 46054 | B9: Personal Care | C9: Actual | D9: ='Historical Actuals'!C129 -> 120677 | E9: ='Historical Actuals'!D129 -> 8.9 | F9: ='Historical Actuals'!E129 -> 1074.0253 | G9: ='Historical Actuals'!F129 -> 4.56 | H9: ='Historical Actuals'!G129 -> 550.28712 | I9: ='Historical Actuals'!H129 -> 523.73818 | J9: ='Historical Actuals'!I129 -> 0.48764045 | K9: ='Historical Actuals'!J129 -> 79.7 | ... O9: ='Historical Actuals'!N129 -> 0.20720013 | P9: Actual
A10: 46054 | B10: Home Care | C10: Actual | D10: ='Historical Actuals'!C130 -> 97652 | E10: ='Historical Actuals'!D130 -> 10.72 | F10: ='Historical Actuals'!E130 -> 1046.8294 | G10: ='Historical Actuals'!F130 -> 5.93 | H10: ='Historical Actuals'!G130 -> 579.07636 | I10: ='Historical Actuals'!H130 -> 467.75308 | J10: ='Historical Actuals'!I130 -> 0.44682836 | K10: ='Historical Actuals'!J130 -> 62.4 | ... O10: ='Historical Actuals'!N130 -> 0.20638804 | P10: Actual
A11: 46054 | B11: Nutrition & Wellness | C11: Actual | D11: ='Historical Actuals'!C131 -> 77584 | E11: ='Historical Actuals'!D131 -> 15.5 | F11: ='Historical Actuals'!E131 -> 1202.552 | G11: ='Historical Actuals'!F131 -> 8.19 | H11: ='Historical Actuals'!G131 -> 635.41296 | I11: ='Historical Actuals'!H131 -> 567.13904 | J11: ='Historical Actuals'!I131 -> 0.4716129 | K11: ='Historical Actuals'!J131 -> 106.6 | ... O11: ='Historical Actuals'!N131 -> 0.24101996 | P11: Actual
A12: 46054 | B12: Baby & Kids | C12: Actual | D12: ='Historical Actuals'!C132 -> 63523 | E12: ='Historical Actuals'!D132 -> 13.14 | F12: ='Historical Actuals'!E132 -> 834.69222 | G12: ='Historical Actuals'!F132 -> 6.85 | H12: ='Historical Actuals'!G132 -> 435.13255 | I12: ='Historical Actuals'!H132 -> 399.55967 | J12: ='Historical Actuals'!I132 -> 0.47869102 | K12: ='Historical Actuals'!J132 -> 72.8 | ... O12: ='Historical Actuals'!N132 -> 0.20613547 | P12: Actual
A13: 46054 | B13: Leisure & Lifestyle | C13: Actual | D13: ='Historical Actuals'!C133 -> 52083 | E13: ='Historical Actuals'!D133 -> 20.38 | F13: ='Historical Actuals'!E133 -> 1061.4515 | G13: ='Historical Actuals'!F133 -> 11.87 | H13: ='Historical Actuals'!G133 -> 618.22521 | I13: ='Historical Actuals'!H133 -> 443.22633 | J13: ='Historical Actuals'!I133 -> 0.41756624 | K13: ='Historical Actuals'!J133 -> 76.9 | ... O13: ='Historical Actuals'!N133 -> 0.21105658 | P13: Actual
A14: 46082 | B14: Personal Care | C14: Actual | D14: ='Historical Actuals'!C134 -> 130294 | E14: ='Historical Actuals'!D134 -> 8.84 | F14: ='Historical Actuals'!E134 -> 1151.799 | G14: ='Historical Actuals'!F134 -> 4.6 | H14: ='Historical Actuals'!G134 -> 599.3524 | I14: ='Historical Actuals'!H134 -> 552.44656 | J14: ='Historical Actuals'!I134 -> 0.47963801 | K14: ='Historical Actuals'!J134 -> 85.3 | ... O14: ='Historical Actuals'!N134 -> 0.2163108 | P14: Actual
A15: 46082 | B15: Home Care | C15: Actual | D15: ='Historical Actuals'!C135 -> 104872 | E15: ='Historical Actuals'!D135 -> 10.69 | F15: ='Historical Actuals'!E135 -> 1121.0817 | G15: ='Historical Actuals'!F135 -> 5.98 | H15: ='Historical Actuals'!G135 -> 627.13456 | I15: ='Historical Actuals'!H135 -> 493.94712 | J15: ='Historical Actuals'!I135 -> 0.44059869 | K15: ='Historical Actuals'!J135 -> 67.1 | ... O15: ='Historical Actuals'!N135 -> 0.2116234 | P15: Actual
... A48: 46266 | B48: Leisure & Lifestyle | C48: Actual | D48: ='Historical Actuals'!C168 -> 55276 | E48: ='Historical Actuals'!D168 -> 20.59 | F48: ='Historical Actuals'!E168 -> 1138.1328 | G48: ='Historical Actuals'!F168 -> 11.85 | H48: ='Historical Actuals'!G168 -> 655.0206 | I48: ='Historical Actuals'!H168 -> 483.11224 | J48: ='Historical Actuals'!I168 -> 0.4244779 | K48: ='Historical Actuals'!J168 -> 76.4 | ... O48: ='Historical Actuals'!N168 -> 0.23109099 | P48: Actual
A49: 46296 | B49: Personal Care | C49: Forecast | D49: ='Budget 2026'!D49*Assumptions!$B$16 -> 139809.65 | E49: ='Budget 2026'!F49*Assumptions!$C$16 -> 8.8786 | F49: =D49*E49/1000 -> 1241.314 | G49: ='Budget 2026'!H49*Assumptions!$D$16 -> 4.54365 | H49: =D49*G49/1000 -> 635.24614 | I49: =F49-H49 -> 606.06786 | J49: =IFERROR(I49/F49,0) -> 0.48824702 | K49: ='Budget 2026'!M49*Assumptions!$E$16 -> 90.615922 | L49: ='Budget 2026'!N49 -> 215.50003 | M49: ='Budget 2026'!O49*Assumptions!$F$16 -> 88.2855 | N49: =I49-K49-L49-M49 -> 211.66641 | O49: =IFERROR(N49/F49,0) -> 0.17051802 | P49: =Assumptions!$B$6 -> Base
A50: 46296 | B50: Home Care | C50: Forecast | D50: ='Budget 2026'!D50*Assumptions!$B$16 -> 103545.62 | E50: ='Budget 2026'!F50*Assumptions!$C$16 -> 10.67064 | F50: =D50*E50/1000 -> 1104.8981 | G50: ='Budget 2026'!H50*Assumptions!$D$16 -> 5.98926 | H50: =D50*G50/1000 -> 620.16166 | I50: =F50-H50 -> 484.73641 | J50: =IFERROR(I50/F50,0) -> 0.43871595 | K50: ='Budget 2026'!M50*Assumptions!$E$16 -> 67.398783 | L50: ='Budget 2026'!N50 -> 180.19206 | M50: ='Budget 2026'!O50*Assumptions!$F$16 -> 77.418 | N50: =I50-K50-L50-M50 -> 159.72757 | O50: =IFERROR(N50/F50,0) -> 0.14456317 | P50: =Assumptions!$B$6 -> Base
A51: 46296 | B51: Nutrition & Wellness | C51: Forecast | D51: ='Budget 2026'!D51*Assumptions!$B$16 -> 86661.36 | E51: ='Budget 2026'!F51*Assumptions!$C$16 -> 15.61815 | F51: =D51*E51/1000 -> 1353.4901 | G51: ='Budget 2026'!H51*Assumptions!$D$16 -> 8.29432 | H51: =D51*G51/1000 -> 718.79705 | I51: =F51-H51 -> 634.69307 | J51: =IFERROR(I51/F51,0) -> 0.4689307 | K51: ='Budget 2026'!M51*Assumptions!$E$16 -> 115.04666 | L51: ='Budget 2026'!N51 -> 169.65001 | M51: ='Budget 2026'!O51*Assumptions!$F$16 -> 71.448 | N51: =I51-K51-L51-M51 -> 278.5484 | O51: =IFERROR(N51/F51,0) -> 0.2058001 | P51: =Assumptions!$B$6 -> Base
A52: 46296 | B52: Baby & Kids | C52: Forecast | D52: ='Budget 2026'!D52*Assumptions!$B$16 -> 71867.856 | E52: ='Budget 2026'!F52*Assumptions!$C$16 -> 13.11672 | F52: =D52*E52/1000 -> 942.67054 | G52: ='Budget 2026'!H52*Assumptions!$D$16 -> 6.8016 | H52: =D52*G52/1000 -> 488.81641 | I52: =F52-H52 -> 453.85413 | J52: =IFERROR(I52/F52,0) -> 0.48145573 | K52: ='Budget 2026'!M52*Assumptions!$E$16 -> 86.72569 | L52: ='Budget 2026'!N52 -> 149.00023 | M52: ='Budget 2026'!O52*Assumptions!$F$16 -> 65.52 | N52: =I52-K52-L52-M52 -> 152.60822 | O52: =IFERROR(N52/F52,0) -> 0.16188924 | P52: =Assumptions!$B$6 -> Base
A53: 46296 | B53: Leisure & Lifestyle | C53: Forecast | D53: ='Budget 2026'!D53*Assumptions!$B$16 -> 56477.88 | E53: ='Budget 2026'!F53*Assumptions!$C$16 -> 20.4795 | F53: =D53*E53/1000 -> 1156.6387 | G53: ='Budget 2026'!H53*Assumptions!$D$16 -> 11.704 | H53: =D53*G53/1000 -> 661.01711 | I53: =F53-H53 -> 495.62164 | J53: =IFERROR(I53/F53,0) -> 0.42850167 | K53: ='Budget 2026'!M53*Assumptions!$E$16 -> 77.494796 | L53: ='Budget 2026'!N53 -> 127.77794 | M53: ='Budget 2026'!O53*Assumptions!$F$16 -> 61.237 | N53: =I53-K53-L53-M53 -> 229.1119 | O53: =IFERROR(N53/F53,0) -> 0.19808424 | P53: =Assumptions!$B$6 -> Base
A54: 46327 | B54: Personal Care | C54: Forecast | D54: ='Budget 2026'!D54*Assumptions!$B$16 -> 146344.32 | E54: ='Budget 2026'!F54*Assumptions!$C$16 -> 8.8477 | F54: =D54*E54/1000 -> 1294.8107 | G54: ='Budget 2026'!H54*Assumptions!$D$16 -> 4.6161 | H54: =D54*G54/1000 -> 675.54004 | I54: =F54-H54 -> 619.27065 | J54: =IFERROR(I54/F54,0) -> 0.47827119 | K54: ='Budget 2026'!M54*Assumptions!$E$16 -> 94.52118 | L54: ='Budget 2026'!N54 -> 215.50003 | M54: ='Budget 2026'!O54*Assumptions!$F$16 -> 90.666 | N54: =I54-K54-L54-M54 -> 218.58343 | O54: =IFERROR(N54/F54,0) -> 0.16881497 | P54: =Assumptions!$B$6 -> Base
A55: 46327 | B55: Home Care | C55: Forecast | D55: ='Budget 2026'!D55*Assumptions!$B$16 -> 116391.4 | E55: ='Budget 2026'!F55*Assumptions!$C$16 -> 10.71176 | F55: =D55*E55/1000 -> 1246.7567 | G55: ='Budget 2026'!H55*Assumptions!$D$16 -> 5.97888 | H55: =D55*G55/1000 -> 695.89021 | I55: =F55-H55 -> 550.86653 | J55: =IFERROR(I55/F55,0) -> 0.44183962 | K55: ='Budget 2026'!M55*Assumptions!$E$16 -> 76.052161 | L55: ='Budget 2026'!N55 -> 180.19206 | M55: ='Budget 2026'!O55*Assumptions!$F$16 -> 79.074 | N55: =I55-K55-L55-M55 -> 215.54831 | O55: =IFERROR(N55/F55,0) -> 0.17288722 | P55: =Assumptions!$B$6 -> Base
A56: 46327 | B56: Nutrition & Wellness | C56: Forecast | D56: ='Budget 2026'!D56*Assumptions!$B$16 -> 95212.8 | E56: ='Budget 2026'!F56*Assumptions!$C$16 -> 15.6699 | F56: =D56*E56/1000 -> 1491.9751 | G56: ='Budget 2026'!H56*Assumptions!$D$16 -> 8.24222 | H56: =D56*G56/1000 -> 784.76484 | I56: =F56-H56 -> 707.21021 | J56: =IFERROR(I56/F56,0) -> 0.47400941 | K56: ='Budget 2026'!M56*Assumptions!$E$16 -> 126.81788 | L56: ='Budget 2026'!N56 -> 169.65001 | M56: ='Budget 2026'!O56*Assumptions!$F$16 -> 73.32 | N56: =I56-K56-L56-M56 -> 337.42232 | O56: =IFERROR(N56/F56,0) -> 0.22615815 | P56: =Assumptions!$B$6 -> Base
A57: 46327 | B57: Baby & Kids | C57: Forecast | D57: ='Budget 2026'!D57*Assumptions!$B$16 -> 75976.452 | E57: ='Budget 2026'!F57*Assumptions!$C$16 -> 13.06512 | F57: =D57*E57/1000 -> 992.64146 | G57: ='Budget 2026'!H57*Assumptions!$D$16 -> 6.8848 | H57: =D57*G57/1000 -> 523.08268 | I57: =F57-H57 -> 469.55879 | J57: =IFERROR(I57/F57,0) -> 0.47303967 | K57: ='Budget 2026'!M57*Assumptions!$E$16 -> 91.323015 | L57: ='Budget 2026'!N57 -> 149.00023 | M57: ='Budget 2026'!O57*Assumptions!$F$16 -> 63.752 | N57: =I57-K57-L57-M57 -> 165.48354 | O57: =IFERROR(N57/F57,0) -> 0.16671029 | P57: =Assumptions!$B$6 -> Base
A58: 46327 | B58: Leisure & Lifestyle | C58: Forecast | D58: ='Budget 2026'!D58*Assumptions!$B$16 -> 57410.415 | E58: ='Budget 2026'!F58*Assumptions!$C$16 -> 20.48975 | F58: =D58*E58/1000 -> 1176.3251 | G58: ='Budget 2026'!H58*Assumptions!$D$16 -> 11.8503 | H58: =D58*G58/1000 -> 680.33064 | I58: =F58-H58 -> 495.99441 | J58: =IFERROR(I58/F58,0) -> 0.42164741 | K58: ='Budget 2026'!M58*Assumptions!$E$16 -> 78.813778 | L58: ='Budget 2026'!N58 -> 127.77794 | M58: ='Budget 2026'!O58*Assumptions!$F$16 -> 63.6405 | N58: =I58-K58-L58-M58 -> 225.76219 | O58: =IFERROR(N58/F58,0) -> 0.19192161 | P58: =Assumptions!$B$6 -> Base
A59: 46357 | B59: Personal Care | C59: Forecast | D59: ='Budget 2026'!D59*Assumptions!$B$16 -> 155689.51 | E59: ='Budget 2026'!F59*Assumptions!$C$16 -> 8.8683 | F59: =D59*E59/1000 -> 1380.7013 | G59: ='Budget 2026'!H59*Assumptions!$D$16 -> 4.58505 | H59: =D59*G59/1000 -> 713.84421 | I59: =F59-H59 -> 666.85712 | J59: =IFERROR(I59/F59,0) -> 0.48298434 | K59: ='Budget 2026'!M59*Assumptions!$E$16 -> 100.7912 | L59: ='Budget 2026'!N59 -> 215.50003 | M59: ='Budget 2026'!O59*Assumptions!$F$16 -> 90.7695 | N59: =I59-K59-L59-M59 -> 259.79639 | O59: =IFERROR(N59/F59,0) -> 0.18816262 | P59: =Assumptions!$B$6 -> Base
A60: 46357 | B60: Home Care | C60: Forecast | D60: ='Budget 2026'!D60*Assumptions!$B$16 -> 121536.8 | E60: ='Budget 2026'!F60*Assumptions!$C$16 -> 10.83512 | F60: =D60*E60/1000 -> 1316.8658 | G60: ='Budget 2026'!H60*Assumptions!$D$16 -> 5.9685 | H60: =D60*G60/1000 -> 725.39237 | I60: =F60-H60 -> 591.4734 | J60: =IFERROR(I60/F60,0) -> 0.44915239 | K60: ='Budget 2026'!M60*Assumptions!$E$16 -> 80.328812 | L60: ='Budget 2026'!N60 -> 180.19206 | M60: ='Budget 2026'!O60*Assumptions!$F$16 -> 79.3845 | N60: =I60-K60-L60-M60 -> 251.56803 | O60: =IFERROR(N60/F60,0) -> 0.19103544 | P60: =Assumptions!$B$6 -> Base
... A63: 46357 | B63: Leisure & Lifestyle | C63: Forecast | D63: ='Budget 2026'!D63*Assumptions!$B$16 -> 62640.27 | E63: ='Budget 2026'!F63*Assumptions!$C$16 -> 20.36675 | F63: =D63*E63/1000 -> 1275.7787 | G63: ='Budget 2026'!H63*Assumptions!$D$16 -> 11.69355 | H63: =D63*G63/1000 -> 732.48713 | I63: =F63-H63 -> 543.29159 | J63: =IFERROR(I63/F63,0) -> 0.42585096 | K63: ='Budget 2026'!M63*Assumptions!$E$16 -> 85.477174 | L63: ='Budget 2026'!N63 -> 127.77794 | M63: ='Budget 2026'!O63*Assumptions!$F$16 -> 61.655 | N63: =I63-K63-L63-M63 -> 268.38148 | O63: =IFERROR(N63/F63,0) -> 0.21036679 | P63: =Assumptions!$B$6 -> Base

Sheet Variance Analysis
A1: Budget vs Rolling Forecast — Variance Analysis
A3: Monthly performance bridge
A4: Month | B4: Budget Revenue | C4: Forecast Revenue | D4: Revenue Var £ | E4: Revenue Var % | F4: Budget GP | G4: Forecast GP | H4: GP Var £ | I4: Budget EBITDA | J4: Forecast EBITDA | K4: EBITDA Var £ | L4: Budget EBITDA % | M4: Forecast EBITDA %
A5: 46023 | B5: =SUM('Budget 2026'!I4:I8) -> 5159.2979 | C5: =SUM('Rolling Forecast'!F4:F8) -> 5110.5859 | D5: =C5-B5 -> -48.711978 | E5: =IFERROR(D5/B5,0) -> -0.0094415905 | F5: =SUM('Budget 2026'!K4:K8) -> 2397.5828 | G5: =SUM('Rolling Forecast'!I4:I8) -> 2351.0351 | H5: =G5-F5 -> -46.547644 | I5: =SUM('Budget 2026'!P4:P8) -> 824.27256 | J5: =SUM('Rolling Forecast'!N4:N8) -> 1078.8351 | K5: =J5-I5 -> 254.56255 | L5: =IFERROR(I5/B5,0) -> 0.15976448 | M5: =IFERROR(J5/C5,0) -> 0.21109813
A6: 46054 | B6: =SUM('Budget 2026'!I9:I13) -> 5273.8634 | C6: =SUM('Rolling Forecast'!F9:F13) -> 5219.5505 | D6: =C6-B6 -> -54.312858 | E6: =IFERROR(D6/B6,0) -> -0.010298495 | F6: =SUM('Budget 2026'!K9:K13) -> 2435.3654 | G6: =SUM('Rolling Forecast'!I9:I13) -> 2401.4163 | H6: =G6-F6 -> -33.949148 | I6: =SUM('Budget 2026'!P9:P13) -> 860.69777 | J6: =SUM('Rolling Forecast'!N9:N13) -> 1124.5163 | K6: =J6-I6 -> 263.81853 | L6: =IFERROR(I6/B6,0) -> 0.16320062 | M6: =IFERROR(J6/C6,0) -> 0.21544313
A7: 46082 | B7: =SUM('Budget 2026'!I14:I18) -> 5497.3196 | C7: =SUM('Rolling Forecast'!F14:F18) -> 5543.7374 | D7: =C7-B7 -> 46.417864 | E7: =IFERROR(D7/B7,0) -> 0.0084437267 | F7: =SUM('Budget 2026'!K14:K18) -> 2537.0929 | G7: =SUM('Rolling Forecast'!I14:I18) -> 2557.479 | H7: =G7-F7 -> 20.386092 | I7: =SUM('Budget 2026'!P14:P18) -> 886.04063 | J7: =SUM('Rolling Forecast'!N14:N18) -> 1260.079 | K7: =J7-I7 -> 374.03837 | L7: =IFERROR(I7/B7,0) -> 0.16117685 | M7: =IFERROR(J7/C7,0) -> 0.22729774
A8: 46113 | B8: =SUM('Budget 2026'!I19:I23) -> 5581.1522 | C8: =SUM('Rolling Forecast'!F19:F23) -> 5554.7515 | D8: =C8-B8 -> -26.400742 | E8: =IFERROR(D8/B8,0) -> -0.004730339 | F8: =SUM('Budget 2026'!K19:K23) -> 2576.0699 | G8: =SUM('Rolling Forecast'!I19:I23) -> 2544.7213 | H8: =G8-F8 -> -31.34864 | I8: =SUM('Budget 2026'!P19:P23) -> 920.32617 | J8: =SUM('Rolling Forecast'!N19:N23) -> 1254.3213 | K8: =J8-I8 -> 333.99512 | L8: =IFERROR(I8/B8,0) -> 0.16489895 | M8: =IFERROR(J8/C8,0) -> 0.22581051
A9: 46143 | B9: =SUM('Budget 2026'!I24:I28) -> 5627.6947 | C9: =SUM('Rolling Forecast'!F24:F28) -> 5551.7411 | D9: =C9-B9 -> -75.953628 | E9: =IFERROR(D9/B9,0) -> -0.013496402 | F9: =SUM('Budget 2026'!K24:K28) -> 2598.2407 | G9: =SUM('Rolling Forecast'!I24:I28) -> 2551.2537 | H9: =G9-F9 -> -46.986944 | I9: =SUM('Budget 2026'!P24:P28) -> 939.33632 | J9: =SUM('Rolling Forecast'!N24:N28) -> 1240.5537 | K9: =J9-I9 -> 301.21741 | L9: =IFERROR(I9/B9,0) -> 0.16691316 | M9: =IFERROR(J9/C9,0) -> 0.2234531
A10: 46174 | B10: =SUM('Budget 2026'!I29:I33) -> 5765.8793 | C10: =SUM('Rolling Forecast'!F29:F33) -> 5700.2679 | D10: =C10-B10 -> -65.611378 | E10: =IFERROR(D10/B10,0) -> -0.011379249 | F10: =SUM('Budget 2026'!K29:K33) -> 2670.2805 | G10: =SUM('Rolling Forecast'!I29:I33) -> 2639.606 | H10: =G10-F10 -> -30.674435 | I10: =SUM('Budget 2026'!P29:P33) -> 1030.3959 | J10: =SUM('Rolling Forecast'!N29:N33) -> 1345.906 | K10: =J10-I10 -> 315.51014 | L10: =IFERROR(I10/B10,0) -> 0.17870577 | M10: =IFERROR(J10/C10,0) -> 0.23611277
A11: 46204 | B11: =SUM('Budget 2026'!I34:I38) -> 5963.3308 | C11: =SUM('Rolling Forecast'!F34:F38) -> 5898.7152 | D11: =C11-B11 -> -64.615633 | E11: =IFERROR(D11/B11,0) -> -0.010835494 | F11: =SUM('Budget 2026'!K34:K38) -> 2765.6741 | G11: =SUM('Rolling Forecast'!I34:I38) -> 2717.9397 | H11: =G11-F11 -> -47.734421 | I11: =SUM('Budget 2026'!P34:P38) -> 1103.6631 | J11: =SUM('Rolling Forecast'!N34:N38) -> 1390.4397 | K11: =J11-I11 -> 286.77659 | L11: =IFERROR(I11/B11,0) -> 0.18507494 | M11: =IFERROR(J11/C11,0) -> 0.23571908
A12: 46235 | B12: =SUM('Budget 2026'!I39:I43) -> 5670.7887 | C12: =SUM('Rolling Forecast'!F39:F43) -> 5671.2931 | D12: =C12-B12 -> 0.50441215 | E12: =IFERROR(D12/B12,0) -> 8.8949207e-05 | F12: =SUM('Budget 2026'!K39:K43) -> 2598.1802 | G12: =SUM('Rolling Forecast'!I39:I43) -> 2635.7712 | H12: =G12-F12 -> 37.591032 | I12: =SUM('Budget 2026'!P39:P43) -> 954.454 | J12: =SUM('Rolling Forecast'!N39:N43) -> 1333.0712 | K12: =J12-I12 -> 378.61723 | L12: =IFERROR(I12/B12,0) -> 0.16831063 | M12: =IFERROR(J12/C12,0) -> 0.23505596
A13: 46266 | B13: =SUM('Budget 2026'!I44:I48) -> 5539.2845 | C13: =SUM('Rolling Forecast'!F44:F48) -> 5528.9505 | D13: =C13-B13 -> -10.333994 | E13: =IFERROR(D13/B13,0) -> -0.0018655828 | F13: =SUM('Budget 2026'!K44:K48) -> 2577.6748 | G13: =SUM('Rolling Forecast'!I44:I48) -> 2555.0192 | H13: =G13-F13 -> -22.655528 | I13: =SUM('Budget 2026'!P44:P48) -> 953.06336 | J13: =SUM('Rolling Forecast'!N44:N48) -> 1262.6192 | K13: =J13-I13 -> 309.55587 | L13: =IFERROR(I13/B13,0) -> 0.17205532 | M13: =IFERROR(J13/C13,0) -> 0.22836508
A14: 46296 | B14: =SUM('Budget 2026'!I49:I53) -> 5799.0115 | C14: =SUM('Rolling Forecast'!F49:F53) -> 5799.0115 | D14: =C14-B14 -> 0 | E14: =IFERROR(D14/B14,0) -> 0 | F14: =SUM('Budget 2026'!K49:K53) -> 2674.9731 | G14: =SUM('Rolling Forecast'!I49:I53) -> 2674.9731 | H14: =G14-F14 -> 0 | I14: =SUM('Budget 2026'!P49:P53) -> 1031.6625 | J14: =SUM('Rolling Forecast'!N49:N53) -> 1031.6625 | K14: =J14-I14 -> 0 | L14: =IFERROR(I14/B14,0) -> 0.17790316 | M14: =IFERROR(J14/C14,0) -> 0.17790316
A15: 46327 | B15: =SUM('Budget 2026'!I54:I58) -> 6202.509 | C15: =SUM('Rolling Forecast'!F54:F58) -> 6202.509 | D15: =C15-B15 -> 0 | E15: =IFERROR(D15/B15,0) -> 0 | F15: =SUM('Budget 2026'!K54:K58) -> 2842.9006 | G15: =SUM('Rolling Forecast'!I54:I58) -> 2842.9006 | H15: =G15-F15 -> 0 | I15: =SUM('Budget 2026'!P54:P58) -> 1162.7998 | J15: =SUM('Rolling Forecast'!N54:N58) -> 1162.7998 | K15: =J15-I15 -> 0 | L15: =IFERROR(I15/B15,0) -> 0.18747249 | M15: =IFERROR(J15/C15,0) -> 0.18747249
A16: 46357 | B16: =SUM('Budget 2026'!I59:I63) -> 6572.739 | C16: =SUM('Rolling Forecast'!F59:F63) -> 6572.739 | D16: =C16-B16 -> 0 | E16: =IFERROR(D16/B16,0) -> 0 | F16: =SUM('Budget 2026'!K59:K63) -> 3037.3311 | G16: =SUM('Rolling Forecast'!I59:I63) -> 3037.3311 | H16: =G16-F16 -> 0 | I16: =SUM('Budget 2026'!P59:P63) -> 1331.531 | J16: =SUM('Rolling Forecast'!N59:N63) -> 1331.531 | K16: =J16-I16 -> 0 | L16: =IFERROR(I16/B16,0) -> 0.20258389 | M16: =IFERROR(J16/C16,0) -> 0.20258389
A19: Full-year summary by division
A20: Division | B20: Budget Revenue | C20: Forecast Revenue | D20: Revenue Var £ | E20: Budget EBITDA | F20: Forecast EBITDA | G20: EBITDA Var £
A21: Personal Care | B21: ='Budget 2026'!I4+'Budget 2026'!I9+'Budget 2026'!I14+'Budget 2026'!I19+'Budget 2026'!I24+'Budget 2026'!I29+'Budget 2026'!I34+'Budget 2026'!I39+'Budget 2026'!I44+'Budget 2026'!I49+'Budget 2026'!I54+'Budget 2026'!I59 -> 14398.501 | C21: ='Rolling Forecast'!F4+'Rolling Forecast'!F9+'Rolling Forecast'!F14+'Rolling Forecast'!F19+'Rolling Forecast'!F24+'Rolling Forecast'!F29+'Rolling Forecast'!F34+'Rolling Forecast'!F39+'Rolling Forecast'!F44+'Rolling Forecast'!F49+'Rolling Forecast'!F54+'Rolling Forecast'!F59 -> 14213.227 | D21: =C21-B21 -> -185.27342 | E21: ='Budget 2026'!P4+'Budget 2026'!P9+'Budget 2026'!P14+'Budget 2026'!P19+'Budget 2026'!P24+'Budget 2026'!P29+'Budget 2026'!P34+'Budget 2026'!P39+'Budget 2026'!P44+'Budget 2026'!P49+'Budget 2026'!P54+'Budget 2026'!P59 -> 2246.3856 | F21: ='Rolling Forecast'!N4+'Rolling Forecast'!N9+'Rolling Forecast'!N14+'Rolling Forecast'!N19+'Rolling Forecast'!N24+'Rolling Forecast'!N29+'Rolling Forecast'!N34+'Rolling Forecast'!N39+'Rolling Forecast'!N44+'Rolling Forecast'!N49+'Rolling Forecast'!N54+'Rolling Forecast'!N59 -> 2922.7013 | G21: =F21-E21 -> 676.3157
A22: Home Care | B22: ='Budget 2026'!I5+'Budget 2026'!I10+'Budget 2026'!I15+'Budget 2026'!I20+'Budget 2026'!I25+'Budget 2026'!I30+'Budget 2026'!I35+'Budget 2026'!I40+'Budget 2026'!I45+'Budget 2026'!I50+'Budget 2026'!I55+'Budget 2026'!I60 -> 13582.084 | C22: ='Rolling Forecast'!F5+'Rolling Forecast'!F10+'Rolling Forecast'!F15+'Rolling Forecast'!F20+'Rolling Forecast'!F25+'Rolling Forecast'!F30+'Rolling Forecast'!F35+'Rolling Forecast'!F40+'Rolling Forecast'!F45+'Rolling Forecast'!F50+'Rolling Forecast'!F55+'Rolling Forecast'!F60 -> 13627.938 | D22: =C22-B22 -> 45.853575 | E22: ='Budget 2026'!P5+'Budget 2026'!P10+'Budget 2026'!P15+'Budget 2026'!P20+'Budget 2026'!P25+'Budget 2026'!P30+'Budget 2026'!P35+'Budget 2026'!P40+'Budget 2026'!P45+'Budget 2026'!P50+'Budget 2026'!P55+'Budget 2026'!P60 -> 2100.1816 | F22: ='Rolling Forecast'!N5+'Rolling Forecast'!N10+'Rolling Forecast'!N15+'Rolling Forecast'!N20+'Rolling Forecast'!N25+'Rolling Forecast'!N30+'Rolling Forecast'!N35+'Rolling Forecast'!N40+'Rolling Forecast'!N45+'Rolling Forecast'!N50+'Rolling Forecast'!N55+'Rolling Forecast'!N60 -> 2752.5665 | G22: =F22-E22 -> 652.38488
A23: Nutrition & Wellness | B23: ='Budget 2026'!I6+'Budget 2026'!I11+'Budget 2026'!I16+'Budget 2026'!I21+'Budget 2026'!I26+'Budget 2026'!I31+'Budget 2026'!I36+'Budget 2026'!I41+'Budget 2026'!I46+'Budget 2026'!I51+'Budget 2026'!I56+'Budget 2026'!I61 -> 16043.681 | C23: ='Rolling Forecast'!F6+'Rolling Forecast'!F11+'Rolling Forecast'!F16+'Rolling Forecast'!F21+'Rolling Forecast'!F26+'Rolling Forecast'!F31+'Rolling Forecast'!F36+'Rolling Forecast'!F41+'Rolling Forecast'!F46+'Rolling Forecast'!F51+'Rolling Forecast'!F56+'Rolling Forecast'!F61 -> 15755.544 | D23: =C23-B23 -> -288.13647 | E23: ='Budget 2026'!P6+'Budget 2026'!P11+'Budget 2026'!P16+'Budget 2026'!P21+'Budget 2026'!P26+'Budget 2026'!P31+'Budget 2026'!P36+'Budget 2026'!P41+'Budget 2026'!P46+'Budget 2026'!P51+'Budget 2026'!P56+'Budget 2026'!P61 -> 3357.7006 | F23: ='Rolling Forecast'!N6+'Rolling Forecast'!N11+'Rolling Forecast'!N16+'Rolling Forecast'!N21+'Rolling Forecast'!N26+'Rolling Forecast'!N31+'Rolling Forecast'!N36+'Rolling Forecast'!N41+'Rolling Forecast'!N46+'Rolling Forecast'!N51+'Rolling Forecast'!N56+'Rolling Forecast'!N61 -> 3891.0698 | G23: =F23-E23 -> 533.36923
A24: Baby & Kids | B24: ='Budget 2026'!I7+'Budget 2026'!I12+'Budget 2026'!I17+'Budget 2026'!I22+'Budget 2026'!I27+'Budget 2026'!I32+'Budget 2026'!I37+'Budget 2026'!I42+'Budget 2026'!I47+'Budget 2026'!I52+'Budget 2026'!I57+'Budget 2026'!I62 -> 11170.966 | C24: ='Rolling Forecast'!F7+'Rolling Forecast'!F12+'Rolling Forecast'!F17+'Rolling Forecast'!F22+'Rolling Forecast'!F27+'Rolling Forecast'!F32+'Rolling Forecast'!F37+'Rolling Forecast'!F42+'Rolling Forecast'!F47+'Rolling Forecast'!F52+'Rolling Forecast'!F57+'Rolling Forecast'!F62 -> 11069.93 | D24: =C24-B24 -> -101.03541 | E24: ='Budget 2026'!P7+'Budget 2026'!P12+'Budget 2026'!P17+'Budget 2026'!P22+'Budget 2026'!P27+'Budget 2026'!P32+'Budget 2026'!P37+'Budget 2026'!P42+'Budget 2026'!P47+'Budget 2026'!P52+'Budget 2026'!P57+'Budget 2026'!P62 -> 1723.1688 | F24: ='Rolling Forecast'!N7+'Rolling Forecast'!N12+'Rolling Forecast'!N17+'Rolling Forecast'!N22+'Rolling Forecast'!N27+'Rolling Forecast'!N32+'Rolling Forecast'!N37+'Rolling Forecast'!N42+'Rolling Forecast'!N47+'Rolling Forecast'!N52+'Rolling Forecast'!N57+'Rolling Forecast'!N62 -> 2194.4725 | G24: =F24-E24 -> 471.30376
